Workbook

Sheet Sheet1
A1: Cropland | B1: Acres | C1: 27903626 | G1: Acre per farm | H1: =C1/C2 -> 238.52107
B2: Number of Operations | C2: 116986 | G2: Sales per acre | H2: =C20/C1 -> 259.7027
A3: Cropland (excl Harvested & Pastured) | B3: Acres | C3: 12701877
B4: Number of Operations | C4: 46675
A5: All crops failed | B5: Acres | C5: 7351748
B6: Number of Operations | C6: 18551
A7: Cultivated Summer Fallow | B7: Acres | C7: 1451257
B8: Number of Operations | C8: 11492
A9: Idle | B9: Acres | C9: 3898872
B10: Number of Operations | C10: 23723
A11: Harvested | B11: Acres | C11: 12467602
B12: Number of Operations | C12: 81443
A13: Pastured | B13: Acres | C13: 2734147
B14: Number of Operations | C14: 16101
A20: Cropland | B20: Total Sales | C20: 7246647000

Sheet Texas Acres
A1: AG LAND, CROPLAND - ACRES | B1: NAICS CLASSIFICATION: (1111) | C1: 6571967 | E1: =C1/C32 -> 1284.842
A2: AG LAND, CROPLAND - ACRES | B2: NAICS CLASSIFICATION: (1112) | C2: 492463 | E2: =C2/C33 -> 327.65336
A3: AG LAND, CROPLAND - ACRES | B3: NAICS CLASSIFICATION: (1113) | C3: 265150 | D3: =SUM(C1:C3) -> 7329580 | E3: =C3/C34 -> 45.762858
A4: AG LAND, CROPLAND - ACRES | B4: NAICS CLASSIFICATION: (1114) | C4: 130914 | D4: =SUM(C1:C4) -> 7460494 | E4: =C4/C35 -> 79.438107
A5: AG LAND, CROPLAND - ACRES | B5: NAICS CLASSIFICATION: (1119) | C5: 12134458 | D5: =SUM(C1:C5) -> 19594952 | E5: =C5/C36 -> 269.92455
A6: AG LAND, CROPLAND, (EXCL HARVESTED & PASTURED), ALL CROPS FAILED - ACRES | B6: NAICS CLASSIFICATION: (1111) | C6: 1257216
A7: AG LAND, CROPLAND, (EXCL HARVESTED & PASTURED), ALL CROPS FAILED - ACRES | B7: NAICS CLASSIFICATION: (1112) | C7: 159444
A8: AG LAND, CROPLAND, (EXCL HARVESTED & PASTURED), ALL CROPS FAILED - ACRES | B8: NAICS CLASSIFICATION: (1113) | C8: 51530
A9: AG LAND, CROPLAND, (EXCL HARVESTED & PASTURED), ALL CROPS FAILED - ACRES | B9: NAICS CLASSIFICATION: (1114) | C9: 6522
A10: AG LAND, CROPLAND, (EXCL HARVESTED & PASTURED), ALL CROPS FAILED - ACRES | B10: NAICS CLASSIFICATION: (1119) | C10: 4050148 | E10: =SUM(C6:C10) -> 5524860
A11: AG LAND, CROPLAND, (EXCL HARVESTED & PASTURED), CULTIVATED SUMMER FALLOW - ACRES | B11: NAICS CLASSIFICATION: (1111) | C11: 324718
A12: AG LAND, CROPLAND, (EXCL HARVESTED & PASTURED), CULTIVATED SUMMER FALLOW - ACRES | B12: NAICS CLASSIFICATION: (1112) | C12: 12475
A13: AG LAND, CROPLAND, (EXCL HARVESTED & PASTURED), CULTIVATED SUMMER FALLOW - ACRES | B13: NAICS CLASSIFICATION: (1113) | C13: 14843
A14: AG LAND, CROPLAND, (EXCL HARVESTED & PASTURED), CULTIVATED SUMMER FALLOW - ACRES | B14: NAICS CLASSIFICATION: (1114) | C14: 8281
A15: AG LAND, CROPLAND, (EXCL HARVESTED & PASTURED), CULTIVATED SUMMER FALLOW - ACRES | B15: NAICS CLASSIFICATION: (1119) | C15: 506691 | E15: =SUM(C11:C15) -> 867008
A16: AG LAND, CROPLAND, (EXCL HARVESTED & PASTURED), IDLE - ACRES | B16: NAICS CLASSIFICATION: (1111) | C16: 438966
A17: AG LAND, CROPLAND, (EXCL HARVESTED & PASTURED), IDLE - ACRES | B17: NAICS CLASSIFICATION: (1112) | C17: 84049
A18: AG LAND, CROPLAND, (EXCL HARVESTED & PASTURED), IDLE - ACRES | B18: NAICS CLASSIFICATION: (1113) | C18: 31510
A19: AG LAND, CROPLAND, (EXCL HARVESTED & PASTURED), IDLE - ACRES | B19: NAICS CLASSIFICATION: (1114) | C19: 15350
A20: AG LAND, CROPLAND, (EXCL HARVESTED & PASTURED), IDLE - ACRES | B20: NAICS CLASSIFICATION: (1119) | C20: 2399629 | E20: =SUM(C16:C20) -> 2969504
A21: AG LAND, CROPLAND, HARVESTED - ACRES | B21: NAICS CLASSIFICATION: (1111) | C21: 4303703
A22: AG LAND, CROPLAND, HARVESTED - ACRES | B22: NAICS CLASSIFICATION: (1112) | C22: 211000
A23: AG LAND, CROPLAND, HARVESTED - ACRES | B23: NAICS CLASSIFICATION: (1113) | C23: 156652
A24: AG LAND, CROPLAND, HARVESTED - ACRES | B24: NAICS CLASSIFICATION: (1114) | C24: 97247
A25: AG LAND, CROPLAND, HARVESTED - ACRES | B25: NAICS CLASSIFICATION: (1119) | C25: 4695075 | E25: =SUM(C21:C25) -> 9463677
A26: AG LAND, CROPLAND, PASTURED ONLY - ACRES | B26: NAICS CLASSIFICATION: (1111) | C26: 247364
A27: AG LAND, CROPLAND, PASTURED ONLY - ACRES | B27: NAICS CLASSIFICATION: (1112) | C27: 25495
A28: AG LAND, CROPLAND, PASTURED ONLY - ACRES | B28: NAICS CLASSIFICATION: (1113) | C28: 10615
A29: AG LAND, CROPLAND, PASTURED ONLY - ACRES | B29: NAICS CLASSIFICATION: (1114) | C29: 3514
A30: AG LAND, CROPLAND, PASTURED ONLY - ACRES | B30: NAICS CLASSIFICATION: (1119) | C30: 482915 | E30: =SUM(C26:C30) -> 769903
A32: AG LAND, CROPLAND - NUMBER OF OPERATIONS | B32: NAICS CLASSIFICATION: (1111) | C32: 5115
A33: AG LAND, CROPLAND - NUMBER OF OPERATIONS | B33: NAICS CLASSIFICATION: (1112) | C33: 1503
A34: AG LAND, CROPLAND - NUMBER OF OPERATIONS | B34: NAICS CLASSIFICATION: (1113) | C34: 5794 | E34: =SUM(C32:C34) -> 12412
A35: AG LAND, CROPLAND - NUMBER OF OPERATIONS | B35: NAICS CLASSIFICATION: (1114) | C35: 1648 | E35: =SUM(C32:C35) -> 14060
A36: AG LAND, CROPLAND - NUMBER OF OPERATIONS | B36: NAICS CLASSIFICATION: (1119) | C36: 44955 | E36: =SUM(C32:C36) -> 59015
A37: AG LAND, CROPLAND, (EXCL HARVESTED & PASTURED), ALL CROPS FAILED - NUMBER OF OPERATIONS | B37: NAICS CLASSIFICATION: (1111) | C37: 1278
A38: AG LAND, CROPLAND, (EXCL HARVESTED & PASTURED), ALL CROPS FAILED - NUMBER OF OPERATIONS | B38: NAICS CLASSIFICATION: (1112) | C38: 248
A39: AG LAND, CROPLAND, (EXCL HARVESTED & PASTURED), ALL CROPS FAILED - NUMBER OF OPERATIONS | B39: NAICS CLASSIFICATION: (1113) | C39: 609
A40: AG LAND, CROPLAND, (EXCL HARVESTED & PASTURED), ALL CROPS FAILED - NUMBER OF OPERATIONS | B40: NAICS CLASSIFICATION: (1114) | C40: 115
A41: AG LAND, CROPLAND, (EXCL HARVESTED & PASTURED), ALL CROPS FAILED - NUMBER OF OPERATIONS | B41: NAICS CLASSIFICATION: (1119) | C41: 8062 | E41: =SUM(C37:C41) -> 10312
...

Sheet National Acres
A1: AG LAND, CROPLAND - ACRES | B1: NAICS CLASSIFICATION | C1: NAICS CLASSIFICATION: (1111) | D1: 235703790
A2: AG LAND, CROPLAND - ACRES | B2: NAICS CLASSIFICATION | C2: NAICS CLASSIFICATION: (1112) | D2: 7275938
A3: AG LAND, CROPLAND - ACRES | B3: NAICS CLASSIFICATION | C3: NAICS CLASSIFICATION: (1113) | D3: 7631889
A4: AG LAND, CROPLAND - ACRES | B4: NAICS CLASSIFICATION | C4: NAICS CLASSIFICATION: (1114) | D4: 1788459
A5: AG LAND, CROPLAND - ACRES | B5: NAICS CLASSIFICATION | C5: NAICS CLASSIFICATION: (1119) | D5: 61215533 | E5: =SUM(D1:D5) -> 313615609
A6: AG LAND, CROPLAND - NUMBER OF OPERATIONS | B6: NAICS CLASSIFICATION | C6: NAICS CLASSIFICATION: (1111) | D6: 330930
A7: AG LAND, CROPLAND - NUMBER OF OPERATIONS | B7: NAICS CLASSIFICATION | C7: NAICS CLASSIFICATION: (1112) | D7: 41793
A8: AG LAND, CROPLAND - NUMBER OF OPERATIONS | B8: NAICS CLASSIFICATION | C8: NAICS CLASSIFICATION: (1113) | D8: 97343
A9: AG LAND, CROPLAND - NUMBER OF OPERATIONS | B9: NAICS CLASSIFICATION | C9: NAICS CLASSIFICATION: (1114) | D9: 50782
A10: AG LAND, CROPLAND - NUMBER OF OPERATIONS | B10: NAICS CLASSIFICATION | C10: NAICS CLASSIFICATION: (1119) | D10: 418301 | E10: =SUM(D6:D10) -> 939149
A12: Acre per farm | B12: =E5/E10 -> 333.93595

Sheet Net Cash Income
A1: Texas | D1: per acre
A2: INCOME, NET CASH FARM, OF OPERATIONS - NET INCOME, MEASURED IN $ | B2: NAICS CLASSIFICATION: (1111) | C2: 771430000 | D2: =C2/'Texas Acres'!C1 -> 117.3819
A3: INCOME, NET CASH FARM, OF OPERATIONS - NET INCOME, MEASURED IN $ | B3: NAICS CLASSIFICATION: (1112) | C3: 184060000 | D3: =C3/'Texas Acres'!C2 -> 373.75397
A4: INCOME, NET CASH FARM, OF OPERATIONS - NET INCOME, MEASURED IN $ | B4: NAICS CLASSIFICATION: (1113) | C4: 18064000 | D4: =C4/'Texas Acres'!C3 -> 68.127475 | E4: =SUM(C2:C4) -> 973554000
A5: INCOME, NET CASH FARM, OF OPERATIONS - NET INCOME, MEASURED IN $ | B5: NAICS CLASSIFICATION: (1114) | C5: 439527000 | D5: =C5/'Texas Acres'!C4 -> 3357.372 | E5: =SUM(C2:C5) -> 1413081000
A6: INCOME, NET CASH FARM, OF OPERATIONS - NET INCOME, MEASURED IN $ | B6: NAICS CLASSIFICATION: (1119) | C6: 548390000 | D6: =C6/'Texas Acres'!C5 -> 45.192789 | E6: =SUM(C2:C6) -> 1961471000
A7: Total
G8: 1119 | H8: 1111+1112 | I8: 1111 | J8: 1112
A9: Income per acre | C9: =E6/'Texas Acres'!D5 -> 100.10083 | D9: =E5/'Texas Acres'!D4 -> 189.4085 | E9: =E4/'Texas Acres'!D3 -> 132.82535 | G9: =C6/'Texas Acres'!C5 -> 45.192789 | H9: =(C2+C3)/('Texas Acres'!C1+'Texas Acres'!C2) -> 135.25366 | I9: =D2 -> 117.3819 | J9: =D3 -> 373.75397
A10: Income per farm | C10: =E6/'Texas Acres'!E36 -> 33236.821 | D10: =E5/'Texas Acres'!E35 -> 100503.63 | E10: =E4/'Texas Acres'!E34 -> 78436.513 | G10: =C6/'Texas Acres'!C36 -> 12198.643 | H10: =(C2+C3)/('Texas Acres'!C32+'Texas Acres'!C33) -> 144377.46 | I10: =C2/'Texas Acres'!C32 -> 150817.2 | J10: =C3/'Texas Acres'!C33 -> 122461.74
A13: Conventional crop farming excluding fertilizer expenses | C13: Net income | D13: Expenses fertilizer | E13: Total
A14: INCOME, NET CASH FARM, OF OPERATIONS - NET INCOME, MEASURED IN $ | B14: NAICS CLASSIFICATION: (1111) | C14: 771430000 | D14: 466451000 | E14: =C14+D14 -> 1237881000
A15: INCOME, NET CASH FARM, OF OPERATIONS - NET INCOME, MEASURED IN $ | B15: NAICS CLASSIFICATION: (1112) | C15: 184060000 | D15: 64500000 | E15: =C15+D15 -> 248560000
A16: INCOME, NET CASH FARM, OF OPERATIONS - NET INCOME, MEASURED IN $ | B16: NAICS CLASSIFICATION: (1113) | C16: 18064000 | D16: 22845000 | E16: =C16+D16 -> 40909000
A17: INCOME, NET CASH FARM, OF OPERATIONS - NET INCOME, MEASURED IN $ | B17: NAICS CLASSIFICATION: (1114) | C17: 439527000 | D17: 56284000 | E17: =C17+D17 -> 495811000
A18: INCOME, NET CASH FARM, OF OPERATIONS - NET INCOME, MEASURED IN $ | B18: NAICS CLASSIFICATION: (1119) | C18: 548390000 | D18: 409958000 | E18: =C18+D18 -> 958348000
A19: Total | C19: =SUM(C14:C18) -> 1961471000 | D19: =SUM(D14:D18) -> 1020038000 | E19: =SUM(E14:E18) -> 2981509000
A21: Income per acre | C21: =C19/'Texas Acres'!D5 -> 100.10083 | D21: =D19/'Texas Acres'!D5 -> 52.056162 | E21: =E19/'Texas Acres'!D5 -> 152.15699
A22: Income per farm | C22: =C19/'Texas Acres'!E36 -> 33236.821 | E22: =E19/'Texas Acres'!E36 -> 50521.206
A27: USA
A28: INCOME, NET CASH FARM, OF OPERATIONS - NET INCOME, MEASURED IN $ | B28: NAICS CLASSIFICATION: (1111) | C28: 56880196000
A29: INCOME, NET CASH FARM, OF OPERATIONS - NET INCOME, MEASURED IN $ | B29: NAICS CLASSIFICATION: (1112) | C29: 7703300000
A30: INCOME, NET CASH FARM, OF OPERATIONS - NET INCOME, MEASURED IN $ | B30: NAICS CLASSIFICATION: (1113) | C30: 5822093000
A31: INCOME, NET CASH FARM, OF OPERATIONS - NET INCOME, MEASURED IN $ | B31: NAICS CLASSIFICATION: (1114) | C31: 5470565000
A32: INCOME, NET CASH FARM, OF OPERATIONS - NET INCOME, MEASURED IN $ | B32: NAICS CLASSIFICATION: (1119) | C32: 7935805000
A33: Total | C33: =SUM(C28:C32) -> 83811959000
A35: Income per acre | C35: =C33/'National Acres'!E5 -> 267.24422
A36: Income per farm | C36: =C33/'National Acres'!E10 -> 89242.451

Sheet Income
A1: INCOME, FARM-RELATED - RECEIPTS, MEASURED IN $ | B1: NAICS CLASSIFICATION: (1111) | C1: 296224000
A2: INCOME, FARM-RELATED - RECEIPTS, MEASURED IN $ | B2: NAICS CLASSIFICATION: (1112) | C2: 35570000
A3: INCOME, FARM-RELATED - RECEIPTS, MEASURED IN $ | B3: NAICS CLASSIFICATION: (1113) | C3: 54529000
A4: INCOME, FARM-RELATED - RECEIPTS, MEASURED IN $ | B4: NAICS CLASSIFICATION: (1114) | C4: 19958000
A5: INCOME, FARM-RELATED - RECEIPTS, MEASURED IN $ | B5: NAICS CLASSIFICATION: (1119) | C5: 724025000
A6: Total | C6: =SUM(C1:C5) -> 1130306000
A8: Income per acre | C8: =C6/'Texas Acres'!D5 -> 57.68353
A9: Income per farm | C9: =C6/'Texas Acres'!E36 -> 19152.859
A14: INCOME, FARM-RELATED, AG SERVICES, CUSTOMWORK & OTHER - RECEIPTS, MEASURED IN $ | B14: NAICS CLASSIFICATION: (1111) | C14: 28762000
A15: INCOME, FARM-RELATED, AG SERVICES, CUSTOMWORK & OTHER - RECEIPTS, MEASURED IN $ | B15: NAICS CLASSIFICATION: (1112) | C15: 1748000
A16: INCOME, FARM-RELATED, AG SERVICES, CUSTOMWORK & OTHER - RECEIPTS, MEASURED IN $ | B16: NAICS CLASSIFICATION: (1113) | C16: 969000
A17: INCOME, FARM-RELATED, AG SERVICES, CUSTOMWORK & OTHER - RECEIPTS, MEASURED IN $ | B17: NAICS CLASSIFICATION: (1114) | C17: 1564000
A18: INCOME, FARM-RELATED, AG SERVICES, CUSTOMWORK & OTHER - RECEIPTS, MEASURED IN $ | B18: NAICS CLASSIFICATION: (1119) | C18: 50555000
A19: INCOME, FARM-RELATED, AG TOURISM & RECREATIONAL SERVICES - RECEIPTS, MEASURED IN $ | B19: NAICS CLASSIFICATION: (1111) | C19: 2011000
A20: INCOME, FARM-RELATED, AG TOURISM & RECREATIONAL SERVICES - RECEIPTS, MEASURED IN $ | B20: NAICS CLASSIFICATION: (1112) | C20: 265000
A21: INCOME, FARM-RELATED, AG TOURISM & RECREATIONAL SERVICES - RECEIPTS, MEASURED IN $ | B21: NAICS CLASSIFICATION: (1113) | C21: 9243000
A22: INCOME, FARM-RELATED, AG TOURISM & RECREATIONAL SERVICES - RECEIPTS, MEASURED IN $ | B22: NAICS CLASSIFICATION: (1114) | C22: 9175000
A23: INCOME, FARM-RELATED, AG TOURISM & RECREATIONAL SERVICES - RECEIPTS, MEASURED IN $ | B23: NAICS CLASSIFICATION: (1119) | C23: 18962000
A24: INCOME, FARM-RELATED, CROP & ANIMAL INSURANCE PAYMENTS - RECEIPTS, MEASURED IN $ | B24: NAICS CLASSIFICATION: (1111) | C24: 221347000
A25: INCOME, FARM-RELATED, CROP & ANIMAL INSURANCE PAYMENTS - RECEIPTS, MEASURED IN $ | B25: NAICS CLASSIFICATION: (1112) | C25: 28222000
... A53: INCOME, FARM-RELATED, RENT, LAND & BUILDINGS - RECEIPTS, MEASURED IN $ | B53: NAICS CLASSIFICATION: (1119) | C53: 130851000

Sheet Sales
A1: CROP TOTALS - SALES, MEASURED IN $ | B1: NAICS CLASSIFICATION: (1111) | C1: 2516499000
A2: CROP TOTALS - SALES, MEASURED IN $ | B2: NAICS CLASSIFICATION: (1112) | C2: 664547000
A3: CROP TOTALS - SALES, MEASURED IN $ | B3: NAICS CLASSIFICATION: (1113) | C3: 201713000
A4: CROP TOTALS - SALES, MEASURED IN $ | B4: NAICS CLASSIFICATION: (1114) | C4: 1169400000
A5: CROP TOTALS - SALES, MEASURED IN $ | B5: NAICS CLASSIFICATION: (1119) | C5: 2356172000
A6: Total | C6: =SUM(C1:C5) -> 6908331000
A8: Sales per acre | C8: =C6/'Texas Acres'!D5 -> 352.55667

Sheet Expenses
A1: AG SERVICES, CUSTOM SERVICES FOR LIVESTOCK, INCL MEDICAL SUPPLIES & VETERINARY - EXPENSE, MEASURED IN $ | B1: NAICS CLASSIFICATION: (1111) | C1: 4856000
A2: AG SERVICES, CUSTOM SERVICES FOR LIVESTOCK, INCL MEDICAL SUPPLIES & VETERINARY - EXPENSE, MEASURED IN $ | B2: NAICS CLASSIFICATION: (1112) | C2: 386000
A3: AG SERVICES, CUSTOM SERVICES FOR LIVESTOCK, INCL MEDICAL SUPPLIES & VETERINARY - EXPENSE, MEASURED IN $ | B3: NAICS CLASSIFICATION: (1113) | C3: 891000
A4: AG SERVICES, CUSTOM SERVICES FOR LIVESTOCK, INCL MEDICAL SUPPLIES & VETERINARY - EXPENSE, MEASURED IN $ | B4: NAICS CLASSIFICATION: (1114) | C4: 248000
A5: AG SERVICES, CUSTOM SERVICES FOR LIVESTOCK, INCL MEDICAL SUPPLIES & VETERINARY - EXPENSE, MEASURED IN $ | B5: NAICS CLASSIFICATION: (1119) | C5: 15710000 | D5: =SUM(C1:C5) -> 22091000
A6: AG SERVICES, CUSTOMWORK - EXPENSE, MEASURED IN $ | B6: NAICS CLASSIFICATION: (1111) | C6: 102053000
A7: AG SERVICES, CUSTOMWORK - EXPENSE, MEASURED IN $ | B7: NAICS CLASSIFICATION: (1112) | C7: 14683000
A8: AG SERVICES, CUSTOMWORK - EXPENSE, MEASURED IN $ | B8: NAICS CLASSIFICATION: (1113) | C8: 7415000
A9: AG SERVICES, CUSTOMWORK - EXPENSE, MEASURED IN $ | B9: NAICS CLASSIFICATION: (1114) | C9: 8452000
A10: AG SERVICES, CUSTOMWORK - EXPENSE, MEASURED IN $ | B10: NAICS CLASSIFICATION: (1119) | C10: 96302000 | D10: =SUM(C6:C10) -> 228905000
A11: AG SERVICES, MACHINERY RENTAL - EXPENSE, MEASURED IN $ | B11: NAICS CLASSIFICATION: (1111) | C11: 27671000
A12: AG SERVICES, MACHINERY RENTAL - EXPENSE, MEASURED IN $ | B12: NAICS CLASSIFICATION: (1112) | C12: 4191000
A13: AG SERVICES, MACHINERY RENTAL - EXPENSE, MEASURED IN $ | B13: NAICS CLASSIFICATION: (1113) | C13: 2785000
A14: AG SERVICES, MACHINERY RENTAL - EXPENSE, MEASURED IN $ | B14: NAICS CLASSIFICATION: (1114) | C14: 8989000
A15: AG SERVICES, MACHINERY RENTAL - EXPENSE, MEASURED IN $ | B15: NAICS CLASSIFICATION: (1119) | C15: 38751000 | D15: =SUM(C11:C15) -> 82387000
A16: AG SERVICES, OTHER - EXPENSE, MEASURED IN $ | B16: NAICS CLASSIFICATION: (1111) | C16: 124864000
A17: AG SERVICES, OTHER - EXPENSE, MEASURED IN $ | B17: NAICS CLASSIFICATION: (1112) | C17: 34810000
A18: AG SERVICES, OTHER - EXPENSE, MEASURED IN $ | B18: NAICS CLASSIFICATION: (1113) | C18: 23418000
A19: AG SERVICES, OTHER - EXPENSE, MEASURED IN $ | B19: NAICS CLASSIFICATION: (1114) | C19: 49857000
A20: AG SERVICES, OTHER - EXPENSE, MEASURED IN $ | B20: NAICS CLASSIFICATION: (1119) | C20: 184024000 | D20: =SUM(C16:C20) -> 416973000
A21: AG SERVICES, UTILITIES - EXPENSE, MEASURED IN $ | B21: NAICS CLASSIFICATION: (1111) | C21: 111738000
A22: AG SERVICES, UTILITIES - EXPENSE, MEASURED IN $ | B22: NAICS CLASSIFICATION: (1112) | C22: 25605000
A23: AG SERVICES, UTILITIES - EXPENSE, MEASURED IN $ | B23: NAICS CLASSIFICATION: (1113) | C23: 13959000
A24: AG SERVICES, UTILITIES - EXPENSE, MEASURED IN $ | B24: NAICS CLASSIFICATION: (1114) | C24: 32633000
A25: AG SERVICES, UTILITIES - EXPENSE, MEASURED IN $ | B25: NAICS CLASSIFICATION: (1119) | C25: 175212000 | D25: =SUM(C21:C25) -> 359147000
A26: ANIMAL TOTALS, (EXCL BREEDING) - EXPENSE, MEASURED IN $ | B26: NAICS CLASSIFICATION: (1111) | C26: 18618000
A27: ANIMAL TOTALS, (EXCL BREEDING) - EXPENSE, MEASURED IN $ | B27: NAICS CLASSIFICATION: (1112) | C27: 724000
A28: ANIMAL TOTALS, (EXCL BREEDING) - EXPENSE, MEASURED IN $ | B28: NAICS CLASSIFICATION: (1113) | C28: 558000
A29: ANIMAL TOTALS, (EXCL BREEDING) - EXPENSE, MEASURED IN $ | B29: NAICS CLASSIFICATION: (1114) | C29: 373000
A30: ANIMAL TOTALS, (EXCL BREEDING) - EXPENSE, MEASURED IN $ | B30: NAICS CLASSIFICATION: (1119) | C30: 16493000 | D30: =SUM(C26:C30) -> 36766000
A31: ANIMAL TOTALS, BREEDING - EXPENSE, MEASURED IN $ | B31: NAICS CLASSIFICATION: (1111) | C31: 8485000
A32: ANIMAL TOTALS, BREEDING - EXPENSE, MEASURED IN $ | B32: NAICS CLASSIFICATION: (1112) | C32: 916000
A33: ANIMAL TOTALS, BREEDING - EXPENSE, MEASURED IN $ | B33: NAICS CLASSIFICATION: (1113) | C33: 751000
A34: ANIMAL TOTALS, BREEDING - EXPENSE, MEASURED IN $ | B34: NAICS CLASSIFICATION: (1114) | C34: 483000
A35: ANIMAL TOTALS, BREEDING - EXPENSE, MEASURED IN $ | B35: NAICS CLASSIFICATION: (1119) | C35: 14925000 | D35: =SUM(C31:C35) -> 25560000
A36: CHEMICAL TOTALS - EXPENSE, MEASURED IN $ | B36: NAICS CLASSIFICATION: (1111) | C36: 275816000
A37: CHEMICAL TOTALS - EXPENSE, MEASURED IN $ | B37: NAICS CLASSIFICATION: (1112) | C37: 49618000
A38: CHEMICAL TOTALS - EXPENSE, MEASURED IN $ | B38: NAICS CLASSIFICATION: (1113) | C38: 21090000
A39: CHEMICAL TOTALS - EXPENSE, MEASURED IN $ | B39: NAICS CLASSIFICATION: (1114) | C39: 29390000
A40: CHEMICAL TOTALS - EXPENSE, MEASURED IN $ | B40: NAICS CLASSIFICATION: (1119) | C40: 348491000 | D40: =SUM(C36:C40) -> 724405000
...
